Backend error message
---------------------
AttemptID:attempt_1546099638075_0005_m_000000_0 Info:Error: org.apache.pig.backend.executionengine.ExecException: ERROR 0: Error executing function
	at org.apache.pig.scripting.jython.JythonFunction.exec(JythonFunction.java:120)
	at org.apache.pig.backend.hadoop.executionengine.physicalLayer.expressionOperators.POUserFunc.getNext(POUserFunc.java:330)
	at org.apache.pig.backend.hadoop.executionengine.physicalLayer.expressionOperators.POUserFunc.getNextInteger(POUserFunc.java:379)
	at org.apache.pig.backend.hadoop.executionengine.physicalLayer.PhysicalOperator.getNext(PhysicalOperator.java:321)
	at org.apache.pig.backend.hadoop.executionengine.physicalLayer.relationalOperators.POForEach.processPlan(POForEach.java:378)
	at org.apache.pig.backend.hadoop.executionengine.physicalLayer.relationalOperators.POForEach.getNextTuple(POForEach.java:298)
	at org.apache.pig.backend.hadoop.executionengine.mapReduceLayer.PigGenericMapBase.runPipeline(PigGenericMapBase.java:282)
	at org.apache.pig.backend.hadoop.executionengine.mapReduceLayer.PigGenericMapBase.map(PigGenericMapBase.java:277)
	at org.apache.pig.backend.hadoop.executionengine.mapReduceLayer.PigGenericMapBase.map(PigGenericMapBase.java:64)
	at org.apache.hadoop.mapreduce.Mapper.run(Mapper.java:145)
	at org.apache.hadoop.mapred.MapTask.runNewMapper(MapTask.java:793)
	at org.apache.hadoop.mapred.MapTask.run(MapTask.java:341)
	at org.apache.hadoop.mapred.YarnChild$2.run(YarnChild.java:164)
	at java.security.AccessController.doPrivileged(Native Method)
	at javax.security.auth.Subject.doAs(Subject.java:422)
	at org.apache.hadoop.security.UserGroupInformation.doAs(UserGroupInformation.java:1924)
	at org.apache.hadoop.mapred.YarnChild.main(YarnChild.java:158)
Caused by: Traceback (most recent call last):
  File "/home/cloudera/Repositories/Temp/difference.py", line 15, in latestYear
    for i,k in reversed(row):
ValueError: need more than 1 value to unpack

	at org.python.core.Py.ValueError(Py.java:309)
	at org.python.core.Py.unpackSequence(Py.java:1777)
	at org.python.pycode._pyx7.latestYear$2(/home/cloudera/Repositories/Temp/difference.py:21)
	at org.python.pycode._pyx7.call_function(/home/cloudera/Repositories/Temp/difference.py)
	at org.python.core.PyTableCode.call(PyTableCode.java:165)
	at org.python.core.PyBaseCode.call(PyBaseCode.java:301)
	at org.python.core.PyFunction.function___call__(PyFunction.java:376)
	at org.python.core.PyFunction.__call__(PyFunction.java:371)
	at org.python.core.PyFunction.__call__(PyFunction.java:361)
	at org.python.core.PyFunction.__call__(PyFunction.java:356)
	at org.apache.pig.scripting.jython.JythonFunction.exec(JythonFunction.java:117)
	... 16 more

Backend error message
---------------------
AttemptID:attempt_1546099638075_0005_m_000000_1 Info:Error: org.apache.pig.backend.executionengine.ExecException: ERROR 0: Error executing function
	at org.apache.pig.scripting.jython.JythonFunction.exec(JythonFunction.java:120)
	at org.apache.pig.backend.hadoop.executionengine.physicalLayer.expressionOperators.POUserFunc.getNext(POUserFunc.java:330)
	at org.apache.pig.backend.hadoop.executionengine.physicalLayer.expressionOperators.POUserFunc.getNextInteger(POUserFunc.java:379)
	at org.apache.pig.backend.hadoop.executionengine.physicalLayer.PhysicalOperator.getNext(PhysicalOperator.java:321)
	at org.apache.pig.backend.hadoop.executionengine.physicalLayer.relationalOperators.POForEach.processPlan(POForEach.java:378)
	at org.apache.pig.backend.hadoop.executionengine.physicalLayer.relationalOperators.POForEach.getNextTuple(POForEach.java:298)
	at org.apache.pig.backend.hadoop.executionengine.mapReduceLayer.PigGenericMapBase.runPipeline(PigGenericMapBase.java:282)
	at org.apache.pig.backend.hadoop.executionengine.mapReduceLayer.PigGenericMapBase.map(PigGenericMapBase.java:277)
	at org.apache.pig.backend.hadoop.executionengine.mapReduceLayer.PigGenericMapBase.map(PigGenericMapBase.java:64)
	at org.apache.hadoop.mapreduce.Mapper.run(Mapper.java:145)
	at org.apache.hadoop.mapred.MapTask.runNewMapper(MapTask.java:793)
	at org.apache.hadoop.mapred.MapTask.run(MapTask.java:341)
	at org.apache.hadoop.mapred.YarnChild$2.run(YarnChild.java:164)
	at java.security.AccessController.doPrivileged(Native Method)
	at javax.security.auth.Subject.doAs(Subject.java:422)
	at org.apache.hadoop.security.UserGroupInformation.doAs(UserGroupInformation.java:1924)
	at org.apache.hadoop.mapred.YarnChild.main(YarnChild.java:158)
Caused by: Traceback (most recent call last):
  File "/home/cloudera/Repositories/Temp/difference.py", line 15, in latestYear
    for i,k in reversed(row):
ValueError: need more than 1 value to unpack

	at org.python.core.Py.ValueError(Py.java:309)
	at org.python.core.Py.unpackSequence(Py.java:1777)
	at org.python.pycode._pyx7.latestYear$2(/home/cloudera/Repositories/Temp/difference.py:21)
	at org.python.pycode._pyx7.call_function(/home/cloudera/Repositories/Temp/difference.py)
	at org.python.core.PyTableCode.call(PyTableCode.java:165)
	at org.python.core.PyBaseCode.call(PyBaseCode.java:301)
	at org.python.core.PyFunction.function___call__(PyFunction.java:376)
	at org.python.core.PyFunction.__call__(PyFunction.java:371)
	at org.python.core.PyFunction.__call__(PyFunction.java:361)
	at org.python.core.PyFunction.__call__(PyFunction.java:356)
	at org.apache.pig.scripting.jython.JythonFunction.exec(JythonFunction.java:117)
	... 16 more

Backend error message
---------------------
AttemptID:attempt_1546099638075_0005_m_000000_2 Info:Error: org.apache.pig.backend.executionengine.ExecException: ERROR 0: Error executing function
	at org.apache.pig.scripting.jython.JythonFunction.exec(JythonFunction.java:120)
	at org.apache.pig.backend.hadoop.executionengine.physicalLayer.expressionOperators.POUserFunc.getNext(POUserFunc.java:330)
	at org.apache.pig.backend.hadoop.executionengine.physicalLayer.expressionOperators.POUserFunc.getNextInteger(POUserFunc.java:379)
	at org.apache.pig.backend.hadoop.executionengine.physicalLayer.PhysicalOperator.getNext(PhysicalOperator.java:321)
	at org.apache.pig.backend.hadoop.executionengine.physicalLayer.relationalOperators.POForEach.processPlan(POForEach.java:378)
	at org.apache.pig.backend.hadoop.executionengine.physicalLayer.relationalOperators.POForEach.getNextTuple(POForEach.java:298)
	at org.apache.pig.backend.hadoop.executionengine.mapReduceLayer.PigGenericMapBase.runPipeline(PigGenericMapBase.java:282)
	at org.apache.pig.backend.hadoop.executionengine.mapReduceLayer.PigGenericMapBase.map(PigGenericMapBase.java:277)
	at org.apache.pig.backend.hadoop.executionengine.mapReduceLayer.PigGenericMapBase.map(PigGenericMapBase.java:64)
	at org.apache.hadoop.mapreduce.Mapper.run(Mapper.java:145)
	at org.apache.hadoop.mapred.MapTask.runNewMapper(MapTask.java:793)
	at org.apache.hadoop.mapred.MapTask.run(MapTask.java:341)
	at org.apache.hadoop.mapred.YarnChild$2.run(YarnChild.java:164)
	at java.security.AccessController.doPrivileged(Native Method)
	at javax.security.auth.Subject.doAs(Subject.java:422)
	at org.apache.hadoop.security.UserGroupInformation.doAs(UserGroupInformation.java:1924)
	at org.apache.hadoop.mapred.YarnChild.main(YarnChild.java:158)
Caused by: Traceback (most recent call last):
  File "/home/cloudera/Repositories/Temp/difference.py", line 15, in latestYear
    for i,k in reversed(row):
ValueError: need more than 1 value to unpack

	at org.python.core.Py.ValueError(Py.java:309)
	at org.python.core.Py.unpackSequence(Py.java:1777)
	at org.python.pycode._pyx7.latestYear$2(/home/cloudera/Repositories/Temp/difference.py:21)
	at org.python.pycode._pyx7.call_function(/home/cloudera/Repositories/Temp/difference.py)
	at org.python.core.PyTableCode.call(PyTableCode.java:165)
	at org.python.core.PyBaseCode.call(PyBaseCode.java:301)
	at org.python.core.PyFunction.function___call__(PyFunction.java:376)
	at org.python.core.PyFunction.__call__(PyFunction.java:371)
	at org.python.core.PyFunction.__call__(PyFunction.java:361)
	at org.python.core.PyFunction.__call__(PyFunction.java:356)
	at org.apache.pig.scripting.jython.JythonFunction.exec(JythonFunction.java:117)
	... 16 more

Backend error message
---------------------
AttemptID:attempt_1546099638075_0005_m_000000_3 Info:Error: org.apache.pig.backend.executionengine.ExecException: ERROR 0: Error executing function
	at org.apache.pig.scripting.jython.JythonFunction.exec(JythonFunction.java:120)
	at org.apache.pig.backend.hadoop.executionengine.physicalLayer.expressionOperators.POUserFunc.getNext(POUserFunc.java:330)
	at org.apache.pig.backend.hadoop.executionengine.physicalLayer.expressionOperators.POUserFunc.getNextInteger(POUserFunc.java:379)
	at org.apache.pig.backend.hadoop.executionengine.physicalLayer.PhysicalOperator.getNext(PhysicalOperator.java:321)
	at org.apache.pig.backend.hadoop.executionengine.physicalLayer.relationalOperators.POForEach.processPlan(POForEach.java:378)
	at org.apache.pig.backend.hadoop.executionengine.physicalLayer.relationalOperators.POForEach.getNextTuple(POForEach.java:298)
	at org.apache.pig.backend.hadoop.executionengine.mapReduceLayer.PigGenericMapBase.runPipeline(PigGenericMapBase.java:282)
	at org.apache.pig.backend.hadoop.executionengine.mapReduceLayer.PigGenericMapBase.map(PigGenericMapBase.java:277)
	at org.apache.pig.backend.hadoop.executionengine.mapReduceLayer.PigGenericMapBase.map(PigGenericMapBase.java:64)
	at org.apache.hadoop.mapreduce.Mapper.run(Mapper.java:145)
	at org.apache.hadoop.mapred.MapTask.runNewMapper(MapTask.java:793)
	at org.apache.hadoop.mapred.MapTask.run(MapTask.java:341)
	at org.apache.hadoop.mapred.YarnChild$2.run(YarnChild.java:164)
	at java.security.AccessController.doPrivileged(Native Method)
	at javax.security.auth.Subject.doAs(Subject.java:422)
	at org.apache.hadoop.security.UserGroupInformation.doAs(UserGroupInformation.java:1924)
	at org.apache.hadoop.mapred.YarnChild.main(YarnChild.java:158)
Caused by: Traceback (most recent call last):
  File "/home/cloudera/Repositories/Temp/difference.py", line 15, in latestYear
    for i,k in reversed(row):
ValueError: need more than 1 value to unpack

	at org.python.core.Py.ValueError(Py.java:309)
	at org.python.core.Py.unpackSequence(Py.java:1777)
	at org.python.pycode._pyx7.latestYear$2(/home/cloudera/Repositories/Temp/difference.py:21)
	at org.python.pycode._pyx7.call_function(/home/cloudera/Repositories/Temp/difference.py)
	at org.python.core.PyTableCode.call(PyTableCode.java:165)
	at org.python.core.PyBaseCode.call(PyBaseCode.java:301)
	at org.python.core.PyFunction.function___call__(PyFunction.java:376)
	at org.python.core.PyFunction.__call__(PyFunction.java:371)
	at org.python.core.PyFunction.__call__(PyFunction.java:361)
	at org.python.core.PyFunction.__call__(PyFunction.java:356)
	at org.apache.pig.scripting.jython.JythonFunction.exec(JythonFunction.java:117)
	... 16 more

Pig Stack Trace
---------------
ERROR 2997: Unable to recreate exception from backed error: AttemptID:attempt_1546099638075_0005_m_000000_3 Info:Error: org.apache.pig.backend.executionengine.ExecException: ERROR 0: Error executing function
	at org.apache.pig.scripting.jython.JythonFunction.exec(JythonFunction.java:120)
	at org.apache.pig.backend.hadoop.executionengine.physicalLayer.expressionOperators.POUserFunc.getNext(POUserFunc.java:330)
	at org.apache.pig.backend.hadoop.executionengine.physicalLayer.expressionOperators.POUserFunc.getNextInteger(POUserFunc.java:379)
	at org.apache.pig.backend.hadoop.executionengine.physicalLayer.PhysicalOperator.getNext(PhysicalOperator.java:321)
	at org.apache.pig.backend.hadoop.executionengine.physicalLayer.relationalOperators.POForEach.processPlan(POForEach.java:378)
	at org.apache.pig.backend.hadoop.executionengine.physicalLayer.relationalOperators.POForEach.getNextTuple(POForEach.java:298)
	at org.apache.pig.backend.hadoop.executionengine.mapReduceLayer.PigGenericMapBase.runPipeline(PigGenericMapBase.java:282)
	at org.apache.pig.backend.hadoop.executionengine.mapReduceLayer.PigGenericMapBase.map(PigGenericMapBase.java:277)
	at org.apache.pig.backend.hadoop.executionengine.mapReduceLayer.PigGenericMapBase.map(PigGenericMapBase.java:64)
	at org.apache.hadoop.mapreduce.Mapper.run(Mapper.java:145)
	at org.apache.hadoop.mapred.MapTask.runNewMapper(MapTask.java:793)
	at org.apache.hadoop.mapred.MapTask.run(MapTask.java:341)
	at org.apache.hadoop.mapred.YarnChild$2.run(YarnChild.java:164)
	at java.security.AccessController.doPrivileged(Native Method)
	at javax.security.auth.Subject.doAs(Subject.java:422)
	at org.apache.hadoop.security.UserGroupInformation.doAs(UserGroupInformation.java:1924)
	at org.apache.hadoop.mapred.YarnChild.main(YarnChild.java:158)
Caused by: Traceback (most recent call last):
  File "/home/cloudera/Repositories/Temp/difference.py", line 15, in latestYear
    for i,k in reversed(row):
ValueError: need more than 1 value to unpack

	at org.python.core.Py.ValueError(Py.java:309)
	at org.python.core.Py.unpackSequence(Py.java:1777)
	at org.python.pycode._pyx7.latestYear$2(/home/cloudera/Repositories/Temp/difference.py:21)
	at org.python.pycode._pyx7.call_function(/home/cloudera/Repositories/Temp/difference.py)
	at org.python.core.PyTableCode.call(PyTableCode.java:165)
	at org.python.core.PyBaseCode.call(PyBaseCode.java:301)
	at org.python.core.PyFunction.function___call__(PyFunction.java:376)
	at org.python.core.PyFunction.__call__(PyFunction.java:371)
	at org.python.core.PyFunction.__call__(PyFunction.java:361)
	at org.python.core.PyFunction.__call__(PyFunction.java:356)
	at org.apache.pig.scripting.jython.JythonFunction.exec(JythonFunction.java:117)
	... 16 more

org.apache.pig.impl.logicalLayer.FrontendException: ERROR 1066: Unable to open iterator for alias result. Backend error : Unable to recreate exception from backed error: AttemptID:attempt_1546099638075_0005_m_000000_3 Info:Error: org.apache.pig.backend.executionengine.ExecException: ERROR 0: Error executing function
	at org.apache.pig.scripting.jython.JythonFunction.exec(JythonFunction.java:120)
	at org.apache.pig.backend.hadoop.executionengine.physicalLayer.expressionOperators.POUserFunc.getNext(POUserFunc.java:330)
	at org.apache.pig.backend.hadoop.executionengine.physicalLayer.expressionOperators.POUserFunc.getNextInteger(POUserFunc.java:379)
	at org.apache.pig.backend.hadoop.executionengine.physicalLayer.PhysicalOperator.getNext(PhysicalOperator.java:321)
	at org.apache.pig.backend.hadoop.executionengine.physicalLayer.relationalOperators.POForEach.processPlan(POForEach.java:378)
	at org.apache.pig.backend.hadoop.executionengine.physicalLayer.relationalOperators.POForEach.getNextTuple(POForEach.java:298)
	at org.apache.pig.backend.hadoop.executionengine.mapReduceLayer.PigGenericMapBase.runPipeline(PigGenericMapBase.java:282)
	at org.apache.pig.backend.hadoop.executionengine.mapReduceLayer.PigGenericMapBase.map(PigGenericMapBase.java:277)
	at org.apache.pig.backend.hadoop.executionengine.mapReduceLayer.PigGenericMapBase.map(PigGenericMapBase.java:64)
	at org.apache.hadoop.mapreduce.Mapper.run(Mapper.java:145)
	at org.apache.hadoop.mapred.MapTask.runNewMapper(MapTask.java:793)
	at org.apache.hadoop.mapred.MapTask.run(MapTask.java:341)
	at org.apache.hadoop.mapred.YarnChild$2.run(YarnChild.java:164)
	at java.security.AccessController.doPrivileged(Native Method)
	at javax.security.auth.Subject.doAs(Subject.java:422)
	at org.apache.hadoop.security.UserGroupInformation.doAs(UserGroupInformation.java:1924)
	at org.apache.hadoop.mapred.YarnChild.main(YarnChild.java:158)
Caused by: Traceback (most recent call last):
  File "/home/cloudera/Repositories/Temp/difference.py", line 15, in latestYear
    for i,k in reversed(row):
ValueError: need more than 1 value to unpack

	at org.python.core.Py.ValueError(Py.java:309)
	at org.python.core.Py.unpackSequence(Py.java:1777)
	at org.python.pycode._pyx7.latestYear$2(/home/cloudera/Repositories/Temp/difference.py:21)
	at org.python.pycode._pyx7.call_function(/home/cloudera/Repositories/Temp/difference.py)
	at org.python.core.PyTableCode.call(PyTableCode.java:165)
	at org.python.core.PyBaseCode.call(PyBaseCode.java:301)
	at org.python.core.PyFunction.function___call__(PyFunction.java:376)
	at org.python.core.PyFunction.__call__(PyFunction.java:371)
	at org.python.core.PyFunction.__call__(PyFunction.java:361)
	at org.python.core.PyFunction.__call__(PyFunction.java:356)
	at org.apache.pig.scripting.jython.JythonFunction.exec(JythonFunction.java:117)
	... 16 more

	at org.apache.pig.PigServer.openIterator(PigServer.java:882)
	at org.apache.pig.tools.grunt.GruntParser.processDump(GruntParser.java:774)
	at org.apache.pig.tools.pigscript.parser.PigScriptParser.parse(PigScriptParser.java:372)
	at org.apache.pig.tools.grunt.GruntParser.parseStopOnError(GruntParser.java:198)
	at org.apache.pig.tools.grunt.GruntParser.parseStopOnError(GruntParser.java:173)
	at org.apache.pig.tools.grunt.Grunt.run(Grunt.java:69)
	at org.apache.pig.Main.run(Main.java:547)
	at org.apache.pig.Main.main(Main.java:158)
	at sun.reflect.NativeMethodAccessorImpl.invoke0(Native Method)
	at sun.reflect.NativeMethodAccessorImpl.invoke(NativeMethodAccessorImpl.java:62)
	at sun.reflect.DelegatingMethodAccessorImpl.invoke(DelegatingMethodAccessorImpl.java:43)
	at java.lang.reflect.Method.invoke(Method.java:498)
	at org.apache.hadoop.util.RunJar.run(RunJar.java:226)
	at org.apache.hadoop.util.RunJar.main(RunJar.java:141)
Caused by: org.apache.pig.backend.executionengine.ExecException: ERROR 2997: Unable to recreate exception from backed error: AttemptID:attempt_1546099638075_0005_m_000000_3 Info:Error: org.apache.pig.backend.executionengine.ExecException: ERROR 0: Error executing function
	at org.apache.pig.scripting.jython.JythonFunction.exec(JythonFunction.java:120)
	at org.apache.pig.backend.hadoop.executionengine.physicalLayer.expressionOperators.POUserFunc.getNext(POUserFunc.java:330)
	at org.apache.pig.backend.hadoop.executionengine.physicalLayer.expressionOperators.POUserFunc.getNextInteger(POUserFunc.java:379)
	at org.apache.pig.backend.hadoop.executionengine.physicalLayer.PhysicalOperator.getNext(PhysicalOperator.java:321)
	at org.apache.pig.backend.hadoop.executionengine.physicalLayer.relationalOperators.POForEach.processPlan(POForEach.java:378)
	at org.apache.pig.backend.hadoop.executionengine.physicalLayer.relationalOperators.POForEach.getNextTuple(POForEach.java:298)
	at org.apache.pig.backend.hadoop.executionengine.mapReduceLayer.PigGenericMapBase.runPipeline(PigGenericMapBase.java:282)
	at org.apache.pig.backend.hadoop.executionengine.mapReduceLayer.PigGenericMapBase.map(PigGenericMapBase.java:277)
	at org.apache.pig.backend.hadoop.executionengine.mapReduceLayer.PigGenericMapBase.map(PigGenericMapBase.java:64)
	at org.apache.hadoop.mapreduce.Mapper.run(Mapper.java:145)
	at org.apache.hadoop.mapred.MapTask.runNewMapper(MapTask.java:793)
	at org.apache.hadoop.mapred.MapTask.run(MapTask.java:341)
	at org.apache.hadoop.mapred.YarnChild$2.run(YarnChild.java:164)
	at java.security.AccessController.doPrivileged(Native Method)
	at javax.security.auth.Subject.doAs(Subject.java:422)
	at org.apache.hadoop.security.UserGroupInformation.doAs(UserGroupInformation.java:1924)
	at org.apache.hadoop.mapred.YarnChild.main(YarnChild.java:158)
Caused by: Traceback (most recent call last):
  File "/home/cloudera/Repositories/Temp/difference.py", line 15, in latestYear
    for i,k in reversed(row):
ValueError: need more than 1 value to unpack

	at org.python.core.Py.ValueError(Py.java:309)
	at org.python.core.Py.unpackSequence(Py.java:1777)
	at org.python.pycode._pyx7.latestYear$2(/home/cloudera/Repositories/Temp/difference.py:21)
	at org.python.pycode._pyx7.call_function(/home/cloudera/Repositories/Temp/difference.py)
	at org.python.core.PyTableCode.call(PyTableCode.java:165)
	at org.python.core.PyBaseCode.call(PyBaseCode.java:301)
	at org.python.core.PyFunction.function___call__(PyFunction.java:376)
	at org.python.core.PyFunction.__call__(PyFunction.java:371)
	at org.python.core.PyFunction.__call__(PyFunction.java:361)
	at org.python.core.PyFunction.__call__(PyFunction.java:356)
	at org.apache.pig.scripting.jython.JythonFunction.exec(JythonFunction.java:117)
	... 16 more

	at org.apache.pig.backend.hadoop.executionengine.mapReduceLayer.Launcher.getErrorMessages(Launcher.java:217)
	at org.apache.pig.backend.hadoop.executionengine.mapReduceLayer.Launcher.getStats(Launcher.java:151)
	at org.apache.pig.backend.hadoop.executionengine.mapReduceLayer.MapReduceLauncher.launchPig(MapReduceLauncher.java:428)
	at org.apache.pig.PigServer.launchPlan(PigServer.java:1334)
	at org.apache.pig.PigServer.executeCompiledLogicalPlan(PigServer.java:1319)
	at org.apache.pig.PigServer.storeEx(PigServer.java:990)
	at org.apache.pig.PigServer.store(PigServer.java:954)
	at org.apache.pig.PigServer.openIterator(PigServer.java:867)
	... 13 more
================================================================================
Pig Stack Trace
---------------
ERROR 1000: Error during parsing. Encountered " <PATH> "+ "" at line 1, column 1.
Was expecting one of:
    <EOF> 
    "cat" ...
    "clear" ...
    "fs" ...
    "sh" ...
    "cd" ...
    "cp" ...
    "copyFromLocal" ...
    "copyToLocal" ...
    "dump" ...
    "\\d" ...
    "describe" ...
    "\\de" ...
    "aliases" ...
    "explain" ...
    "\\e" ...
    "help" ...
    "history" ...
    "kill" ...
    "ls" ...
    "mv" ...
    "mkdir" ...
    "pwd" ...
    "quit" ...
    "\\q" ...
    "register" ...
    "rm" ...
    "rmf" ...
    "set" ...
    "illustrate" ...
    "\\i" ...
    "run" ...
    "exec" ...
    "scriptDone" ...
    "" ...
    "" ...
    <EOL> ...
    ";" ...
    

org.apache.pig.tools.pigscript.parser.ParseException: Encountered " <PATH> "+ "" at line 1, column 1.
Was expecting one of:
    <EOF> 
    "cat" ...
    "clear" ...
    "fs" ...
    "sh" ...
    "cd" ...
    "cp" ...
    "copyFromLocal" ...
    "copyToLocal" ...
    "dump" ...
    "\\d" ...
    "describe" ...
    "\\de" ...
    "aliases" ...
    "explain" ...
    "\\e" ...
    "help" ...
    "history" ...
    "kill" ...
    "ls" ...
    "mv" ...
    "mkdir" ...
    "pwd" ...
    "quit" ...
    "\\q" ...
    "register" ...
    "rm" ...
    "rmf" ...
    "set" ...
    "illustrate" ...
    "\\i" ...
    "run" ...
    "exec" ...
    "scriptDone" ...
    "" ...
    "" ...
    <EOL> ...
    ";" ...
    
	at org.apache.pig.tools.pigscript.parser.PigScriptParser.generateParseException(PigScriptParser.java:1428)
	at org.apache.pig.tools.pigscript.parser.PigScriptParser.handle_invalid_command(PigScriptParser.java:1236)
	at org.apache.pig.tools.pigscript.parser.PigScriptParser.parse(PigScriptParser.java:710)
	at org.apache.pig.tools.grunt.GruntParser.parseStopOnError(GruntParser.java:198)
	at org.apache.pig.tools.grunt.GruntParser.parseStopOnError(GruntParser.java:173)
	at org.apache.pig.tools.grunt.Grunt.run(Grunt.java:69)
	at org.apache.pig.Main.run(Main.java:547)
	at org.apache.pig.Main.main(Main.java:158)
	at sun.reflect.NativeMethodAccessorImpl.invoke0(Native Method)
	at sun.reflect.NativeMethodAccessorImpl.invoke(NativeMethodAccessorImpl.java:62)
	at sun.reflect.DelegatingMethodAccessorImpl.invoke(DelegatingMethodAccessorImpl.java:43)
	at java.lang.reflect.Method.invoke(Method.java:498)
	at org.apache.hadoop.util.RunJar.run(RunJar.java:226)
	at org.apache.hadoop.util.RunJar.main(RunJar.java:141)
================================================================================
