Backend error message
---------------------
AttemptID:attempt_1546099638075_0004_m_000000_0 Info:Error: org.apache.pig.backend.executionengine.ExecException: ERROR 0: Exception while executing (Name: newResult: Filter[bag] - scope-566 Operator Key: scope-566): org.apache.pig.backend.executionengine.ExecException: ERROR 0: Error executing function
	at org.apache.pig.backend.hadoop.executionengine.physicalLayer.PhysicalOperator.processInput(PhysicalOperator.java:289)
	at org.apache.pig.backend.hadoop.executionengine.physicalLayer.relationalOperators.POFilter.getNextTuple(POFilter.java:95)
	at org.apache.pig.backend.hadoop.executionengine.mapReduceLayer.PigGenericMapBase.runPipeline(PigGenericMapBase.java:282)
	at org.apache.pig.backend.hadoop.executionengine.mapReduceLayer.PigGenericMapBase.map(PigGenericMapBase.java:277)
	at org.apache.pig.backend.hadoop.executionengine.mapReduceLayer.PigGenericMapBase.map(PigGenericMapBase.java:64)
	at org.apache.hadoop.mapreduce.Mapper.run(Mapper.java:145)
	at org.apache.hadoop.mapred.MapTask.runNewMapper(MapTask.java:793)
	at org.apache.hadoop.mapred.MapTask.run(MapTask.java:341)
	at org.apache.hadoop.mapred.YarnChild$2.run(YarnChild.java:164)
	at java.security.AccessController.doPrivileged(Native Method)
	at javax.security.auth.Subject.doAs(Subject.java:422)
	at org.apache.hadoop.security.UserGroupInformation.doAs(UserGroupInformation.java:1924)
	at org.apache.hadoop.mapred.YarnChild.main(YarnChild.java:158)
Caused by: org.apache.pig.backend.executionengine.ExecException: ERROR 0: Error executing function
	at org.apache.pig.scripting.jython.JythonFunction.exec(JythonFunction.java:120)
	at org.apache.pig.backend.hadoop.executionengine.physicalLayer.expressionOperators.POUserFunc.getNext(POUserFunc.java:330)
	at org.apache.pig.backend.hadoop.executionengine.physicalLayer.expressionOperators.POUserFunc.getNextInteger(POUserFunc.java:379)
	at org.apache.pig.backend.hadoop.executionengine.physicalLayer.PhysicalOperator.getNext(PhysicalOperator.java:321)
	at org.apache.pig.backend.hadoop.executionengine.physicalLayer.relationalOperators.POForEach.processPlan(POForEach.java:378)
	at org.apache.pig.backend.hadoop.executionengine.physicalLayer.relationalOperators.POForEach.getNextTuple(POForEach.java:298)
	at org.apache.pig.backend.hadoop.executionengine.physicalLayer.PhysicalOperator.processInput(PhysicalOperator.java:281)
	... 12 more
Caused by: Traceback (most recent call last):
  File "difference.py", line 15, in latestYear
ValueError: need more than 1 value to unpack

	at org.python.core.Py.ValueError(Py.java:309)
	at org.python.core.Py.unpackSequence(Py.java:1777)
	at org.python.pycode._pyx7.latestYear$2(difference.py:21)
	at org.python.pycode._pyx7.call_function(difference.py)
	at org.python.core.PyTableCode.call(PyTableCode.java:165)
	at org.python.core.PyBaseCode.call(PyBaseCode.java:301)
	at org.python.core.PyFunction.function___call__(PyFunction.java:376)
	at org.python.core.PyFunction.__call__(PyFunction.java:371)
	at org.python.core.PyFunction.__call__(PyFunction.java:361)
	at org.python.core.PyFunction.__call__(PyFunction.java:356)
	at org.apache.pig.scripting.jython.JythonFunction.exec(JythonFunction.java:117)
	... 18 more

Backend error message
---------------------
AttemptID:attempt_1546099638075_0004_m_000000_1 Info:Error: org.apache.pig.backend.executionengine.ExecException: ERROR 0: Exception while executing (Name: newResult: Filter[bag] - scope-566 Operator Key: scope-566): org.apache.pig.backend.executionengine.ExecException: ERROR 0: Error executing function
	at org.apache.pig.backend.hadoop.executionengine.physicalLayer.PhysicalOperator.processInput(PhysicalOperator.java:289)
	at org.apache.pig.backend.hadoop.executionengine.physicalLayer.relationalOperators.POFilter.getNextTuple(POFilter.java:95)
	at org.apache.pig.backend.hadoop.executionengine.mapReduceLayer.PigGenericMapBase.runPipeline(PigGenericMapBase.java:282)
	at org.apache.pig.backend.hadoop.executionengine.mapReduceLayer.PigGenericMapBase.map(PigGenericMapBase.java:277)
	at org.apache.pig.backend.hadoop.executionengine.mapReduceLayer.PigGenericMapBase.map(PigGenericMapBase.java:64)
	at org.apache.hadoop.mapreduce.Mapper.run(Mapper.java:145)
	at org.apache.hadoop.mapred.MapTask.runNewMapper(MapTask.java:793)
	at org.apache.hadoop.mapred.MapTask.run(MapTask.java:341)
	at org.apache.hadoop.mapred.YarnChild$2.run(YarnChild.java:164)
	at java.security.AccessController.doPrivileged(Native Method)
	at javax.security.auth.Subject.doAs(Subject.java:422)
	at org.apache.hadoop.security.UserGroupInformation.doAs(UserGroupInformation.java:1924)
	at org.apache.hadoop.mapred.YarnChild.main(YarnChild.java:158)
Caused by: org.apache.pig.backend.executionengine.ExecException: ERROR 0: Error executing function
	at org.apache.pig.scripting.jython.JythonFunction.exec(JythonFunction.java:120)
	at org.apache.pig.backend.hadoop.executionengine.physicalLayer.expressionOperators.POUserFunc.getNext(POUserFunc.java:330)
	at org.apache.pig.backend.hadoop.executionengine.physicalLayer.expressionOperators.POUserFunc.getNextInteger(POUserFunc.java:379)
	at org.apache.pig.backend.hadoop.executionengine.physicalLayer.PhysicalOperator.getNext(PhysicalOperator.java:321)
	at org.apache.pig.backend.hadoop.executionengine.physicalLayer.relationalOperators.POForEach.processPlan(POForEach.java:378)
	at org.apache.pig.backend.hadoop.executionengine.physicalLayer.relationalOperators.POForEach.getNextTuple(POForEach.java:298)
	at org.apache.pig.backend.hadoop.executionengine.physicalLayer.PhysicalOperator.processInput(PhysicalOperator.java:281)
	... 12 more
Caused by: Traceback (most recent call last):
  File "difference.py", line 15, in latestYear
ValueError: need more than 1 value to unpack

	at org.python.core.Py.ValueError(Py.java:309)
	at org.python.core.Py.unpackSequence(Py.java:1777)
	at org.python.pycode._pyx7.latestYear$2(difference.py:21)
	at org.python.pycode._pyx7.call_function(difference.py)
	at org.python.core.PyTableCode.call(PyTableCode.java:165)
	at org.python.core.PyBaseCode.call(PyBaseCode.java:301)
	at org.python.core.PyFunction.function___call__(PyFunction.java:376)
	at org.python.core.PyFunction.__call__(PyFunction.java:371)
	at org.python.core.PyFunction.__call__(PyFunction.java:361)
	at org.python.core.PyFunction.__call__(PyFunction.java:356)
	at org.apache.pig.scripting.jython.JythonFunction.exec(JythonFunction.java:117)
	... 18 more

Backend error message
---------------------
AttemptID:attempt_1546099638075_0004_m_000000_2 Info:Error: org.apache.pig.backend.executionengine.ExecException: ERROR 0: Exception while executing (Name: newResult: Filter[bag] - scope-566 Operator Key: scope-566): org.apache.pig.backend.executionengine.ExecException: ERROR 0: Error executing function
	at org.apache.pig.backend.hadoop.executionengine.physicalLayer.PhysicalOperator.processInput(PhysicalOperator.java:289)
	at org.apache.pig.backend.hadoop.executionengine.physicalLayer.relationalOperators.POFilter.getNextTuple(POFilter.java:95)
	at org.apache.pig.backend.hadoop.executionengine.mapReduceLayer.PigGenericMapBase.runPipeline(PigGenericMapBase.java:282)
	at org.apache.pig.backend.hadoop.executionengine.mapReduceLayer.PigGenericMapBase.map(PigGenericMapBase.java:277)
	at org.apache.pig.backend.hadoop.executionengine.mapReduceLayer.PigGenericMapBase.map(PigGenericMapBase.java:64)
	at org.apache.hadoop.mapreduce.Mapper.run(Mapper.java:145)
	at org.apache.hadoop.mapred.MapTask.runNewMapper(MapTask.java:793)
	at org.apache.hadoop.mapred.MapTask.run(MapTask.java:341)
	at org.apache.hadoop.mapred.YarnChild$2.run(YarnChild.java:164)
	at java.security.AccessController.doPrivileged(Native Method)
	at javax.security.auth.Subject.doAs(Subject.java:422)
	at org.apache.hadoop.security.UserGroupInformation.doAs(UserGroupInformation.java:1924)
	at org.apache.hadoop.mapred.YarnChild.main(YarnChild.java:158)
Caused by: org.apache.pig.backend.executionengine.ExecException: ERROR 0: Error executing function
	at org.apache.pig.scripting.jython.JythonFunction.exec(JythonFunction.java:120)
	at org.apache.pig.backend.hadoop.executionengine.physicalLayer.expressionOperators.POUserFunc.getNext(POUserFunc.java:330)
	at org.apache.pig.backend.hadoop.executionengine.physicalLayer.expressionOperators.POUserFunc.getNextInteger(POUserFunc.java:379)
	at org.apache.pig.backend.hadoop.executionengine.physicalLayer.PhysicalOperator.getNext(PhysicalOperator.java:321)
	at org.apache.pig.backend.hadoop.executionengine.physicalLayer.relationalOperators.POForEach.processPlan(POForEach.java:378)
	at org.apache.pig.backend.hadoop.executionengine.physicalLayer.relationalOperators.POForEach.getNextTuple(POForEach.java:298)
	at org.apache.pig.backend.hadoop.executionengine.physicalLayer.PhysicalOperator.processInput(PhysicalOperator.java:281)
	... 12 more
Caused by: Traceback (most recent call last):
  File "difference.py", line 15, in latestYear
ValueError: need more than 1 value to unpack

	at org.python.core.Py.ValueError(Py.java:309)
	at org.python.core.Py.unpackSequence(Py.java:1777)
	at org.python.pycode._pyx7.latestYear$2(difference.py:21)
	at org.python.pycode._pyx7.call_function(difference.py)
	at org.python.core.PyTableCode.call(PyTableCode.java:165)
	at org.python.core.PyBaseCode.call(PyBaseCode.java:301)
	at org.python.core.PyFunction.function___call__(PyFunction.java:376)
	at org.python.core.PyFunction.__call__(PyFunction.java:371)
	at org.python.core.PyFunction.__call__(PyFunction.java:361)
	at org.python.core.PyFunction.__call__(PyFunction.java:356)
	at org.apache.pig.scripting.jython.JythonFunction.exec(JythonFunction.java:117)
	... 18 more

Backend error message
---------------------
AttemptID:attempt_1546099638075_0004_m_000000_3 Info:Error: org.apache.pig.backend.executionengine.ExecException: ERROR 0: Exception while executing (Name: newResult: Filter[bag] - scope-566 Operator Key: scope-566): org.apache.pig.backend.executionengine.ExecException: ERROR 0: Error executing function
	at org.apache.pig.backend.hadoop.executionengine.physicalLayer.PhysicalOperator.processInput(PhysicalOperator.java:289)
	at org.apache.pig.backend.hadoop.executionengine.physicalLayer.relationalOperators.POFilter.getNextTuple(POFilter.java:95)
	at org.apache.pig.backend.hadoop.executionengine.mapReduceLayer.PigGenericMapBase.runPipeline(PigGenericMapBase.java:282)
	at org.apache.pig.backend.hadoop.executionengine.mapReduceLayer.PigGenericMapBase.map(PigGenericMapBase.java:277)
	at org.apache.pig.backend.hadoop.executionengine.mapReduceLayer.PigGenericMapBase.map(PigGenericMapBase.java:64)
	at org.apache.hadoop.mapreduce.Mapper.run(Mapper.java:145)
	at org.apache.hadoop.mapred.MapTask.runNewMapper(MapTask.java:793)
	at org.apache.hadoop.mapred.MapTask.run(MapTask.java:341)
	at org.apache.hadoop.mapred.YarnChild$2.run(YarnChild.java:164)
	at java.security.AccessController.doPrivileged(Native Method)
	at javax.security.auth.Subject.doAs(Subject.java:422)
	at org.apache.hadoop.security.UserGroupInformation.doAs(UserGroupInformation.java:1924)
	at org.apache.hadoop.mapred.YarnChild.main(YarnChild.java:158)
Caused by: org.apache.pig.backend.executionengine.ExecException: ERROR 0: Error executing function
	at org.apache.pig.scripting.jython.JythonFunction.exec(JythonFunction.java:120)
	at org.apache.pig.backend.hadoop.executionengine.physicalLayer.expressionOperators.POUserFunc.getNext(POUserFunc.java:330)
	at org.apache.pig.backend.hadoop.executionengine.physicalLayer.expressionOperators.POUserFunc.getNextInteger(POUserFunc.java:379)
	at org.apache.pig.backend.hadoop.executionengine.physicalLayer.PhysicalOperator.getNext(PhysicalOperator.java:321)
	at org.apache.pig.backend.hadoop.executionengine.physicalLayer.relationalOperators.POForEach.processPlan(POForEach.java:378)
	at org.apache.pig.backend.hadoop.executionengine.physicalLayer.relationalOperators.POForEach.getNextTuple(POForEach.java:298)
	at org.apache.pig.backend.hadoop.executionengine.physicalLayer.PhysicalOperator.processInput(PhysicalOperator.java:281)
	... 12 more
Caused by: Traceback (most recent call last):
  File "difference.py", line 15, in latestYear
ValueError: need more than 1 value to unpack

	at org.python.core.Py.ValueError(Py.java:309)
	at org.python.core.Py.unpackSequence(Py.java:1777)
	at org.python.pycode._pyx7.latestYear$2(difference.py:21)
	at org.python.pycode._pyx7.call_function(difference.py)
	at org.python.core.PyTableCode.call(PyTableCode.java:165)
	at org.python.core.PyBaseCode.call(PyBaseCode.java:301)
	at org.python.core.PyFunction.function___call__(PyFunction.java:376)
	at org.python.core.PyFunction.__call__(PyFunction.java:371)
	at org.python.core.PyFunction.__call__(PyFunction.java:361)
	at org.python.core.PyFunction.__call__(PyFunction.java:356)
	at org.apache.pig.scripting.jython.JythonFunction.exec(JythonFunction.java:117)
	... 18 more

Pig Stack Trace
---------------
ERROR 2997: Unable to recreate exception from backed error: AttemptID:attempt_1546099638075_0004_m_000000_3 Info:Error: org.apache.pig.backend.executionengine.ExecException: ERROR 0: Exception while executing (Name: newResult: Filter[bag] - scope-566 Operator Key: scope-566): org.apache.pig.backend.executionengine.ExecException: ERROR 0: Error executing function
	at org.apache.pig.backend.hadoop.executionengine.physicalLayer.PhysicalOperator.processInput(PhysicalOperator.java:289)
	at org.apache.pig.backend.hadoop.executionengine.physicalLayer.relationalOperators.POFilter.getNextTuple(POFilter.java:95)
	at org.apache.pig.backend.hadoop.executionengine.mapReduceLayer.PigGenericMapBase.runPipeline(PigGenericMapBase.java:282)
	at org.apache.pig.backend.hadoop.executionengine.mapReduceLayer.PigGenericMapBase.map(PigGenericMapBase.java:277)
	at org.apache.pig.backend.hadoop.executionengine.mapReduceLayer.PigGenericMapBase.map(PigGenericMapBase.java:64)
	at org.apache.hadoop.mapreduce.Mapper.run(Mapper.java:145)
	at org.apache.hadoop.mapred.MapTask.runNewMapper(MapTask.java:793)
	at org.apache.hadoop.mapred.MapTask.run(MapTask.java:341)
	at org.apache.hadoop.mapred.YarnChild$2.run(YarnChild.java:164)
	at java.security.AccessController.doPrivileged(Native Method)
	at javax.security.auth.Subject.doAs(Subject.java:422)
	at org.apache.hadoop.security.UserGroupInformation.doAs(UserGroupInformation.java:1924)
	at org.apache.hadoop.mapred.YarnChild.main(YarnChild.java:158)
Caused by: org.apache.pig.backend.executionengine.ExecException: ERROR 0: Error executing function
	at org.apache.pig.scripting.jython.JythonFunction.exec(JythonFunction.java:120)
	at org.apache.pig.backend.hadoop.executionengine.physicalLayer.expressionOperators.POUserFunc.getNext(POUserFunc.java:330)
	at org.apache.pig.backend.hadoop.executionengine.physicalLayer.expressionOperators.POUserFunc.getNextInteger(POUserFunc.java:379)
	at org.apache.pig.backend.hadoop.executionengine.physicalLayer.PhysicalOperator.getNext(PhysicalOperator.java:321)
	at org.apache.pig.backend.hadoop.executionengine.physicalLayer.relationalOperators.POForEach.processPlan(POForEach.java:378)
	at org.apache.pig.backend.hadoop.executionengine.physicalLayer.relationalOperators.POForEach.getNextTuple(POForEach.java:298)
	at org.apache.pig.backend.hadoop.executionengine.physicalLayer.PhysicalOperator.processInput(PhysicalOperator.java:281)
	... 12 more
Caused by: Traceback (most recent call last):
  File "difference.py", line 15, in latestYear
ValueError: need more than 1 value to unpack

	at org.python.core.Py.ValueError(Py.java:309)
	at org.python.core.Py.unpackSequence(Py.java:1777)
	at org.python.pycode._pyx7.latestYear$2(difference.py:21)
	at org.python.pycode._pyx7.call_function(difference.py)
	at org.python.core.PyTableCode.call(PyTableCode.java:165)
	at org.python.core.PyBaseCode.call(PyBaseCode.java:301)
	at org.python.core.PyFunction.function___call__(PyFunction.java:376)
	at org.python.core.PyFunction.__call__(PyFunction.java:371)
	at org.python.core.PyFunction.__call__(PyFunction.java:361)
	at org.python.core.PyFunction.__call__(PyFunction.java:356)
	at org.apache.pig.scripting.jython.JythonFunction.exec(JythonFunction.java:117)
	... 18 more

org.apache.pig.backend.executionengine.ExecException: ERROR 2997: Unable to recreate exception from backed error: AttemptID:attempt_1546099638075_0004_m_000000_3 Info:Error: org.apache.pig.backend.executionengine.ExecException: ERROR 0: Exception while executing (Name: newResult: Filter[bag] - scope-566 Operator Key: scope-566): org.apache.pig.backend.executionengine.ExecException: ERROR 0: Error executing function
	at org.apache.pig.backend.hadoop.executionengine.physicalLayer.PhysicalOperator.processInput(PhysicalOperator.java:289)
	at org.apache.pig.backend.hadoop.executionengine.physicalLayer.relationalOperators.POFilter.getNextTuple(POFilter.java:95)
	at org.apache.pig.backend.hadoop.executionengine.mapReduceLayer.PigGenericMapBase.runPipeline(PigGenericMapBase.java:282)
	at org.apache.pig.backend.hadoop.executionengine.mapReduceLayer.PigGenericMapBase.map(PigGenericMapBase.java:277)
	at org.apache.pig.backend.hadoop.executionengine.mapReduceLayer.PigGenericMapBase.map(PigGenericMapBase.java:64)
	at org.apache.hadoop.mapreduce.Mapper.run(Mapper.java:145)
	at org.apache.hadoop.mapred.MapTask.runNewMapper(MapTask.java:793)
	at org.apache.hadoop.mapred.MapTask.run(MapTask.java:341)
	at org.apache.hadoop.mapred.YarnChild$2.run(YarnChild.java:164)
	at java.security.AccessController.doPrivileged(Native Method)
	at javax.security.auth.Subject.doAs(Subject.java:422)
	at org.apache.hadoop.security.UserGroupInformation.doAs(UserGroupInformation.java:1924)
	at org.apache.hadoop.mapred.YarnChild.main(YarnChild.java:158)
Caused by: org.apache.pig.backend.executionengine.ExecException: ERROR 0: Error executing function
	at org.apache.pig.scripting.jython.JythonFunction.exec(JythonFunction.java:120)
	at org.apache.pig.backend.hadoop.executionengine.physicalLayer.expressionOperators.POUserFunc.getNext(POUserFunc.java:330)
	at org.apache.pig.backend.hadoop.executionengine.physicalLayer.expressionOperators.POUserFunc.getNextInteger(POUserFunc.java:379)
	at org.apache.pig.backend.hadoop.executionengine.physicalLayer.PhysicalOperator.getNext(PhysicalOperator.java:321)
	at org.apache.pig.backend.hadoop.executionengine.physicalLayer.relationalOperators.POForEach.processPlan(POForEach.java:378)
	at org.apache.pig.backend.hadoop.executionengine.physicalLayer.relationalOperators.POForEach.getNextTuple(POForEach.java:298)
	at org.apache.pig.backend.hadoop.executionengine.physicalLayer.PhysicalOperator.processInput(PhysicalOperator.java:281)
	... 12 more
Caused by: Traceback (most recent call last):
  File "difference.py", line 15, in latestYear
ValueError: need more than 1 value to unpack

	at org.python.core.Py.ValueError(Py.java:309)
	at org.python.core.Py.unpackSequence(Py.java:1777)
	at org.python.pycode._pyx7.latestYear$2(difference.py:21)
	at org.python.pycode._pyx7.call_function(difference.py)
	at org.python.core.PyTableCode.call(PyTableCode.java:165)
	at org.python.core.PyBaseCode.call(PyBaseCode.java:301)
	at org.python.core.PyFunction.function___call__(PyFunction.java:376)
	at org.python.core.PyFunction.__call__(PyFunction.java:371)
	at org.python.core.PyFunction.__call__(PyFunction.java:361)
	at org.python.core.PyFunction.__call__(PyFunction.java:356)
	at org.apache.pig.scripting.jython.JythonFunction.exec(JythonFunction.java:117)
	... 18 more

	at org.apache.pig.backend.hadoop.executionengine.mapReduceLayer.Launcher.getErrorMessages(Launcher.java:217)
	at org.apache.pig.backend.hadoop.executionengine.mapReduceLayer.Launcher.getStats(Launcher.java:151)
	at org.apache.pig.backend.hadoop.executionengine.mapReduceLayer.MapReduceLauncher.launchPig(MapReduceLauncher.java:428)
	at org.apache.pig.PigServer.launchPlan(PigServer.java:1334)
	at org.apache.pig.PigServer.executeCompiledLogicalPlan(PigServer.java:1319)
	at org.apache.pig.PigServer.execute(PigServer.java:1309)
	at org.apache.pig.PigServer.executeBatch(PigServer.java:387)
	at org.apache.pig.PigServer.executeBatch(PigServer.java:365)
	at org.apache.pig.tools.grunt.GruntParser.executeBatch(GruntParser.java:140)
	at org.apache.pig.tools.grunt.GruntParser.parseStopOnError(GruntParser.java:202)
	at org.apache.pig.tools.grunt.GruntParser.parseStopOnError(GruntParser.java:173)
	at org.apache.pig.tools.grunt.Grunt.exec(Grunt.java:84)
	at org.apache.pig.Main.run(Main.java:613)
	at org.apache.pig.Main.main(Main.java:158)
	at sun.reflect.NativeMethodAccessorImpl.invoke0(Native Method)
	at sun.reflect.NativeMethodAccessorImpl.invoke(NativeMethodAccessorImpl.java:62)
	at sun.reflect.DelegatingMethodAccessorImpl.invoke(DelegatingMethodAccessorImpl.java:43)
	at java.lang.reflect.Method.invoke(Method.java:498)
	at org.apache.hadoop.util.RunJar.run(RunJar.java:226)
	at org.apache.hadoop.util.RunJar.main(RunJar.java:141)
================================================================================
